Workbook

Sheet ÍNDICE
A1: Estimaciones de población por sexo, departamento y año calendario. Años 2022-2035
A2: Índice de cuadros
A4: ='02-CABA'!A1 -> Cuadro 1. Ciudad Autónoma de Buenos Aires. Población estimada al 1.° de julio de cada año calendario, por sexo, según comuna. Años 2022-2035 | J4: "
A5: ='06-BUENOS AIRES'!A1 -> Cuadro 2. Provincia de Buenos Aires. Población estimada al 1.° de julio de cada año calendario, por sexo, según partido. Años 2022-2035
A6: ='10-CATAMARCA'!A1 -> Cuadro 3. Provincia de Catamarca. Población estimada al 1.° de julio de cada año calendario, por sexo, según departamento. Años 2022-2035
A7: ='14-CÓRDOBA'!A1 -> Cuadro 4. Provincia de Córdoba. Población estimada al 1.° de julio de cada año calendario, por sexo, según departamento. Años 2022-2035
A8: ='18-CORRIENTES'!A1 -> Cuadro 5. Provincia de Corrientes. Población estimada al 1.° de julio de cada año calendario, por sexo, según departamento. Años 2022-2035
A9: ='22-CHACO'!A1 -> Cuadro 6. Provincia del Chaco. Población estimada al 1.° de julio de cada año calendario, por sexo, según departamento. Años 2022-2035
A10: ='26-CHUBUT'!A1 -> Cuadro 7. Provincia del Chubut. Población estimada al 1.° de julio de cada año calendario, por sexo, según departamento. Años 2022-2035
A11: ='30-ENTRE RÍOS'!A1 -> Cuadro 8. Provincia de Entre Ríos. Población estimada al 1.° de julio de cada año calendario, por sexo, según departamento. Años 2022-2035
A12: ='34-FORMOSA'!A1 -> Cuadro 9. Provincia de Formosa. Población estimada al 1.° de julio de cada año calendario, por sexo, según departamento. Años 2022-2035
A13: ='38-JUJUY'!A1 -> Cuadro 10. Provincia de Jujuy. Población estimada al 1.° de julio de cada año calendario, por sexo, según departamento. Años 2022-2035
A14: ='42-LA PAMPA'!A1 -> Cuadro 11. Provincia de La Pampa. Población estimada al 1.° de julio de cada año calendario, por sexo, según departamento. Años 2022-2035
A15: ='46-LA RIOJA'!A1 -> Cuadro 12. Provincia de La Rioja. Población estimada al 1.° de julio de cada año calendario, por sexo, según departamento. Años 2022-2035
A16: ='50-MENDOZA'!A1 -> Cuadro 13. Provincia de Mendoza. Población estimada al 1.° de julio de cada año calendario, por sexo, según departamento. Años 2022-2035
A17: ='54-MISIONES'!A1 -> Cuadro 14. Provincia de Misiones. Población estimada al 1.° de julio de cada año calendario, por sexo, según departamento. Años 2022-2035
A18: ='58-NEUQUÉN'!A1 -> Cuadro 15. Provincia del Neuquén. Población estimada al 1.° de julio de cada año calendario, por sexo, según departamento. Años 2022-2035
A19: ='62-RÍO NEGRO'!A1 -> Cuadro 16. Provincia de Río Negro. Población estimada al 1.° de julio de cada año calendario, por sexo, según departamento. Años 2022-2035
A20: ='66-SALTA'!A1 -> Cuadro 17. Provincia de Salta. Población estimada al 1.° de julio de cada año calendario, por sexo, según departamento. Años 2022-2035
A21: ='70-SAN JUAN'!A1 -> Cuadro 18. Provincia de San Juan. Población estimada al 1.° de julio de cada año calendario, por sexo, según departamento. Años 2022-2035
A22: ='74-SAN LUIS'!A1 -> Cuadro 19. Provincia de San Luis. Población estimada al 1.° de julio de cada año calendario, por sexo, según departamento. Años 2022-2035
A23: ='78-SANTA CRUZ'!A1 -> Cuadro 20. Provincia de Santa Cruz. Población estimada al 1.° de julio de cada año calendario, por sexo, según departamento. Años 2022-2035
A24: ='82-SANTA FE'!A1 -> Cuadro 21. Provincia de Santa Fe. Población estimada al 1.° de julio de cada año calendario, por sexo, según departamento. Años 2022-2035
A25: ='86-SANTIAGO DEL ESTERO'!A1 -> Cuadro 22. Provincia de Santiago del Estero. Población estimada al 1.° de julio de cada año calendario, por sexo, según departamento. Años 2022-2035
A26: ='90-TUCUMÁN'!A1 -> Cuadro 23. Provincia de Tucumán. Población estimada al 1.° de julio de cada año calendario, por sexo, según departamento. Años 2022-2035
A27: ='94-TIERRA DEL FUEGO'!A1 -> Cuadro 24. Provincia de Tierra del Fuego, Antártida e Islas del Atlántico Sur. Población estimada al 1.° de julio de cada año calendario, por sexo, según departamento. Años 2022-2035

Sheet 02-CABA
A1: Cuadro 1. Ciudad Autónoma de Buenos Aires. Población estimada al 1.° de julio de cada año calendario, por sexo, según comuna. Años 2022-2035
A2: Ambos sexos
A3: Código | B3: Comuna | C3: 2022 | D3: 2023 | E3: 2024 | F3: 2025 | G3: 2026 | H3: 2027 | I3: 2028 | J3: 2029 | K3: 2030 | L3: 2031 | M3: 2032 | N3: 2033 | O3: 2034 | P3: 2035
A4: 02007 | B4: Comuna 1 | C4: 250490 | D4: 250604 | E4: 250726 | F4: 250848 | G4: 250968 | H4: 251088 | I4: 251206 | J4: 251325 | K4: 251441 | L4: 251553 | M4: 251658 | N4: 251752 | O4: 251836 | P4: 251915
A5: 02014 | B5: Comuna 2 | C5: 154123 | D5: 153154 | E5: 152120 | F5: 151092 | G5: 150090 | H5: 149098 | I5: 148114 | J5: 147143 | K5: 146193 | L5: 145285 | M5: 144439 | N5: 143676 | O5: 143008 | P5: 142387
A6: 02021 | B6: Comuna 3 | C6: 190296 | D6: 188631 | E6: 186899 | F6: 185180 | G6: 183502 | H6: 181842 | I6: 180202 | J6: 178591 | K6: 177015 | L6: 175503 | M6: 174082 | N6: 172775 | O6: 171597 | P6: 170489
A7: 02028 | B7: Comuna 4 | C7: 244077 | D7: 242893 | E7: 241612 | F7: 240339 | G7: 239104 | H7: 237878 | I7: 236662 | J7: 235462 | K7: 234291 | L7: 233183 | M7: 232173 | N7: 231291 | O7: 230557 | P7: 229894
A8: 02035 | B8: Comuna 5 | C8: 189214 | D8: 188018 | E8: 186746 | F8: 185484 | G8: 184253 | H8: 183033 | I8: 181824 | J8: 180630 | K8: 179461 | L8: 178344 | M8: 177303 | N8: 176364 | O8: 175540 | P8: 174772
A9: 02042 | B9: Comuna 6 | C9: 186039 | D9: 184782 | E9: 183451 | F9: 182128 | G9: 180838 | H9: 179558 | I9: 178288 | J9: 177035 | K9: 175807 | L9: 174630 | M9: 173528 | N9: 172527 | O9: 171638 | P9: 170806
A10: 02049 | B10: Comuna 7 | C10: 249834 | D10: 248886 | E10: 247829 | F10: 246768 | G10: 245736 | H10: 244702 | I10: 243669 | J10: 242643 | K10: 241634 | L10: 240683 | M10: 239820 | N10: 239083 | O10: 238487 | P10: 237956
A11: 02056 | B11: Comuna 8 | C11: 232923 | D11: 233387 | E11: 233925 | F11: 234477 | G11: 235021 | H11: 235576 | I11: 236141 | J11: 236711 | K11: 237279 | L11: 237822 | M11: 238318 | N11: 238744 | O11: 239089 | P11: 239399
A12: 02063 | B12: Comuna 9 | C12: 167835 | D12: 166376 | E12: 164856 | F12: 163352 | G12: 161880 | H12: 160424 | I12: 158985 | J12: 157570 | K12: 156186 | L12: 154859 | M12: 153611 | N12: 152461 | O12: 151425 | P12: 150450
A13: 02070 | B13: Comuna 10 | C13: 170037 | D13: 168700 | E13: 167300 | F13: 165909 | G13: 164551 | H13: 163207 | I13: 161875 | J13: 160563 | K13: 159277 | L13: 158045 | M13: 156886 | N13: 155826 | O13: 154873 | P13: 153977
A14: 02077 | B14: Comuna 11 | C14: 195309 | D14: 194216 | E14: 193048 | F14: 191888 | G14: 190761 | H14: 189644 | I14: 188536 | J14: 187445 | K14: 186378 | L14: 185364 | M14: 184429 | N14: 183600 | O14: 182889 | P14: 182237
... A18: 02105 | B18: Comuna 15 | C18: 190629 | D18: 189796 | E18: 188883 | F18: 187973 | G18: 187091 | H18: 186212 | I18: 185338 | J18: 184476 | K18: 183632 | L18: 182835 | M18: 182111 | N18: 181487 | O18: 180975 | P18: 180518
A20: Varones
A21: Código | B21: Comuna | C21: 2022 | D21: 2023 | E21: 2024 | F21: 2025 | G21: 2026 | H21: 2027 | I21: 2028 | J21: 2029 | K21: 2030 | L21: 2031 | M21: 2032 | N21: 2033 | O21: 2034 | P21: 2035
A22: 02007 | B22: Comuna 1 | C22: 118999 | D22: 119056 | E22: 119113 | F22: 119169 | G22: 119224 | H22: 119280 | I22: 119335 | J22: 119390 | K22: 119444 | L22: 119495 | M22: 119543 | N22: 119585 | O22: 119622 | P22: 119656
A23: 02014 | B23: Comuna 2 | C23: 67101 | D23: 66632 | E23: 66169 | F23: 65718 | G23: 65275 | H23: 64832 | I23: 64394 | J23: 63963 | K23: 63543 | L23: 63144 | M23: 62777 | N23: 62450 | O23: 62169 | P23: 61912
A24: 02021 | B24: Comuna 3 | C24: 88846 | D24: 88182 | E24: 87528 | F24: 86889 | G24: 86263 | H24: 85637 | I24: 85019 | J24: 84412 | K24: 83820 | L24: 83258 | M24: 82740 | N24: 82277 | O24: 81876 | P24: 81507
A25: 02028 | B25: Comuna 4 | C25: 114404 | D25: 113923 | E25: 113451 | F25: 112998 | G25: 112557 | H25: 112112 | I25: 111673 | J25: 111242 | K25: 110826 | L25: 110444 | M25: 110113 | N25: 109849 | O25: 109661 | P25: 109510
A26: 02035 | B26: Comuna 5 | C26: 85992 | D26: 85542 | E26: 85099 | F26: 84671 | G26: 84253 | H26: 83833 | I26: 83418 | J26: 83010 | K26: 82614 | L26: 82244 | M26: 81912 | N26: 81631 | O26: 81407 | P26: 81211
A27: 02042 | B27: Comuna 6 | C27: 83833 | D27: 83352 | E27: 82879 | F27: 82420 | G27: 81971 | H27: 81520 | I27: 81073 | J27: 80634 | K27: 80207 | L27: 79805 | M27: 79441 | N27: 79126 | O27: 78866 | P27: 78634
A28: 02049 | B28: Comuna 7 | C28: 115606 | D28: 115273 | E28: 114945 | F28: 114629 | G28: 114320 | H28: 114001 | I28: 113682 | J28: 113366 | K28: 113059 | L28: 112782 | M28: 112551 | N28: 112384 | O28: 112289 | P28: 112228
A29: 02056 | B29: Comuna 8 | C29: 109211 | D29: 109328 | E29: 109448 | F29: 109567 | G29: 109687 | H29: 109820 | I29: 109957 | J29: 110099 | K29: 110240 | L29: 110369 | M29: 110474 | N29: 110545 | O29: 110576 | P29: 110590
A30: 02063 | B30: Comuna 9 | C30: 79741 | D30: 79109 | E30: 78485 | F30: 77878 | G30: 77282 | H30: 76688 | I30: 76102 | J30: 75527 | K30: 74968 | L30: 74438 | M30: 73949 | N30: 73510 | O30: 73129 | P30: 72779
A31: 02070 | B31: Comuna 10 | C31: 79585 | D31: 79089 | E31: 78600 | F31: 78124 | G31: 77658 | H31: 77191 | I31: 76728 | J31: 76273 | K31: 75828 | L31: 75409 | M31: 75025 | N31: 74689 | O31: 74405 | P31: 74147
A32: 02077 | B32: Comuna 11 | C32: 91581 | D32: 91155 | E32: 90737 | F32: 90334 | G32: 89942 | H32: 89547 | I32: 89157 | J32: 88774 | K32: 88404 | L32: 88062 | M32: 87760 | N32: 87513 | O32: 87326 | P32: 87170
... A36: 02105 | B36: Comuna 15 | C36: 88477 | D36: 88161 | E36: 87850 | F36: 87552 | G36: 87263 | H36: 86968 | I36: 86676 | J36: 86390 | K36: 86114 | L36: 85862 | M36: 85648 | N36: 85486 | O36: 85381 | P36: 85304
A38: Mujeres
A39: Código | B39: Comuna | C39: 2022 | D39: 2023 | E39: 2024 | F39: 2025 | G39: 2026 | H39: 2027 | I39: 2028 | J39: 2029 | K39: 2030 | L39: 2031 | M39: 2032 | N39: 2033 | O39: 2034 | P39: 2035
A40: 02007 | B40: Comuna 1 | C40: 131491 | D40: 131548 | E40: 131613 | F40: 131679 | G40: 131744 | H40: 131808 | I40: 131871 | J40: 131935 | K40: 131997 | L40: 132058 | M40: 132115 | N40: 132167 | O40: 132214 | P40: 132259
A41: 02014 | B41: Comuna 2 | C41: 87022 | D41: 86522 | E41: 85951 | F41: 85374 | G41: 84815 | H41: 84266 | I41: 83720 | J41: 83180 | K41: 82650 | L41: 82141 | M41: 81662 | N41: 81226 | O41: 80839 | P41: 80475
A42: 02021 | B42: Comuna 3 | C42: 101450 | D42: 100449 | E42: 99371 | F42: 98291 | G42: 97239 | H42: 96205 | I42: 95183 | J42: 94179 | K42: 93195 | L42: 92245 | M42: 91342 | N42: 90498 | O42: 89721 | P42: 88982
A43: 02028 | B43: Comuna 4 | C43: 129673 | D43: 128970 | E43: 128161 | F43: 127341 | G43: 126547 | H43: 125766 | I43: 124989 | J43: 124220 | K43: 123465 | L43: 122739 | M43: 122060 | N43: 121442 | O43: 120896 | P43: 120384
A44: 02035 | B44: Comuna 5 | C44: 103222 | D44: 102476 | E44: 101647 | F44: 100813 | G44: 100000 | H44: 99200 | I44: 98406 | J44: 97620 | K44: 96847 | L44: 96100 | M44: 95391 | N44: 94733 | O44: 94133 | P44: 93561
A45: 02042 | B45: Comuna 6 | C45: 102206 | D45: 101430 | E45: 100572 | F45: 99708 | G45: 98867 | H45: 98038 | I45: 97215 | J45: 96401 | K45: 95600 | L45: 94825 | M45: 94087 | N45: 93401 | O45: 92772 | P45: 92172
A46: 02049 | B46: Comuna 7 | C46: 134228 | D46: 133613 | E46: 132884 | F46: 132139 | G46: 131416 | H46: 130701 | I46: 129987 | J46: 129277 | K46: 128575 | L46: 127901 | M46: 127269 | N46: 126699 | O46: 126198 | P46: 125728
A47: 02056 | B47: Comuna 8 | C47: 123712 | D47: 124059 | E47: 124477 | F47: 124910 | G47: 125334 | H47: 125756 | I47: 126184 | J47: 126612 | K47: 127039 | L47: 127453 | M47: 127844 | N47: 128199 | O47: 128513 | P47: 128809
A48: 02063 | B48: Comuna 9 | C48: 88094 | D48: 87267 | E48: 86371 | F48: 85474 | G48: 84598 | H48: 83736 | I48: 82883 | J48: 82043 | K48: 81218 | L48: 80421 | M48: 79662 | N48: 78951 | O48: 78296 | P48: 77671
...

Sheet 06-BUENOS AIRES
A1: Cuadro 2. Provincia de Buenos Aires. Población estimada al 1.° de julio de cada año calendario, por sexo, según partido. Años 2022-2035
A2: Ambos sexos
A3: Código | B3: Partido | C3: 2022 | D3: 2023 | E3: 2024 | F3: 2025 | G3: 2026 | H3: 2027 | I3: 2028 | J3: 2029 | K3: 2030 | L3: 2031 | M3: 2032 | N3: 2033 | O3: 2034 | P3: 2035
A4: 39 partidos de la Región Metropolitana de Buenos Aires
A5: 06028 | B5: Almirante Brown | C5: 580807 | D5: 580907 | E5: 581046 | F5: 581174 | G5: 581277 | H5: 581356 | I5: 581420 | J5: 581479 | K5: 581548 | L5: 581639 | M5: 581749 | N5: 581880 | O5: 582027 | P5: 582194
A6: 06035 | B6: Avellaneda | C6: 364962 | D6: 365062 | E6: 365201 | F6: 365332 | G6: 365442 | H6: 365532 | I6: 365607 | J6: 365680 | K6: 365762 | L6: 365862 | M6: 365979 | N6: 366114 | O6: 366265 | P6: 366433
A7: 06091 | B7: Berazategui | C7: 356398 | D7: 356552 | E7: 356767 | F7: 356965 | G7: 357123 | H7: 357248 | I7: 357348 | J7: 357442 | K7: 357552 | L7: 357693 | M7: 357864 | N7: 358066 | O7: 358294 | P7: 358552
A8: 06098 | B8: Berisso | C8: 101167 | D8: 101233 | E8: 101324 | F8: 101408 | G8: 101478 | H8: 101532 | I8: 101576 | J8: 101617 | K8: 101665 | L8: 101727 | M8: 101801 | N8: 101887 | O8: 101985 | P8: 102094
A9: 06119 | B9: Brandsen | C9: 32544 | D9: 32577 | E9: 32625 | F9: 32669 | G9: 32705 | H9: 32733 | I9: 32755 | J9: 32777 | K9: 32801 | L9: 32832 | M9: 32871 | N9: 32915 | O9: 32966 | P9: 33022
A10: 06126 | B10: Campana | C10: 109289 | D10: 109368 | E10: 109479 | F10: 109581 | G10: 109664 | H10: 109731 | I10: 109785 | J10: 109837 | K10: 109896 | L10: 109970 | M10: 110060 | N10: 110164 | O10: 110282 | P10: 110415
A11: 06134 | B11: Cañuelas | C11: 71054 | D11: 71161 | E11: 71313 | F11: 71452 | G11: 71564 | H11: 71651 | I11: 71723 | J11: 71790 | K11: 71869 | L11: 71968 | M11: 72090 | N11: 72231 | O11: 72391 | P11: 72572
A12: 06245 | B12: Ensenada | C12: 64295 | D12: 64334 | E12: 64389 | F12: 64439 | G12: 64479 | H12: 64512 | I12: 64538 | J12: 64564 | K12: 64592 | L12: 64628 | M12: 64673 | N12: 64724 | O12: 64782 | P12: 64848
A13: 06252 | B13: Escobar | C13: 255854 | D13: 256081 | E13: 256398 | F13: 256692 | G13: 256929 | H13: 257118 | I13: 257272 | J13: 257416 | K13: 257584 | L13: 257795 | M13: 258053 | N13: 258351 | O13: 258689 | P13: 259069
A14: 06260 | B14: Esteban Echeverría | C14: 336371 | D14: 336556 | E14: 336814 | F14: 337051 | G14: 337241 | H14: 337389 | I14: 337507 | J14: 337617 | K14: 337747 | L14: 337916 | M14: 338121 | N14: 338361 | O14: 338635 | P14: 338943
A15: 06266 | B15: Exaltación de la Cruz | C15: 40008 | D15: 40066 | E15: 40146 | F15: 40220 | G15: 40280 | H15: 40326 | I15: 40364 | J15: 40400 | K15: 40442 | L15: 40495 | M15: 40560 | N15: 40634 | O15: 40720 | P15: 40816
A16: 06270 | B16: Ezeiza | C16: 200500 | D16: 200704 | E16: 200990 | F16: 201253 | G16: 201465 | H16: 201631 | I16: 201764 | J16: 201888 | K16: 202035 | L16: 202223 | M16: 202451 | N16: 202719 | O16: 203023 | P16: 203364
... A43: 06882 | B43: Zárate | C43: 131226 | D43: 131311 | E43: 131430 | F43: 131539 | G43: 131626 | H43: 131693 | I43: 131748 | J43: 131798 | K43: 131857 | L43: 131933 | M43: 132028 | N43: 132138 | O43: 132264 | P43: 132407
A44: Interior de la provincia de Buenos Aires
A45: 06007 | B45: Adolfo Alsina | C45: 17331 | D45: 17332 | E45: 17332 | F45: 17333 | G45: 17335 | H45: 17336 | I45: 17337 | J45: 17338 | K45: 17340 | L45: 17341 | M45: 17342 | N45: 17344 | O45: 17345 | P45: 17346
A46: 06014 | B46: Adolfo Gonzales Chaves | C46: 12869 | D46: 12872 | E46: 12877 | F46: 12882 | G46: 12886 | H46: 12888 | I46: 12891 | J46: 12894 | K46: 12897 | L46: 12900 | M46: 12903 | N46: 12908 | O46: 12914 | P46: 12920
A47: 06021 | B47: Alberti | C47: 12902 | D47: 12914 | E47: 12931 | F47: 12946 | G47: 12958 | H47: 12968 | I47: 12976 | J47: 12984 | K47: 12993 | L47: 13004 | M47: 13017 | N47: 13033 | O47: 13050 | P47: 13070
A48: 06042 | B48: Ayacucho | C48: 21836 | D48: 21842 | E48: 21851 | F48: 21860 | G48: 21868 | H48: 21873 | I48: 21878 | J48: 21882 | K48: 21888 | L48: 21895 | M48: 21902 | N48: 21911 | O48: 21921 | P48: 21932
A49: 06049 | B49: Azul | C49: 75465 | D49: 75518 | E49: 75592 | F49: 75662 | G49: 75718 | H49: 75763 | I49: 75800 | J49: 75834 | K49: 75874 | L49: 75925 | M49: 75986 | N49: 76057 | O49: 76135 | P49: 76226
A50: 06056 | B50: Bahía Blanca | C50: 335313 | D50: 335481 | E50: 335717 | F50: 335936 | G50: 336115 | H50: 336259 | I50: 336377 | J50: 336489 | K50: 336617 | L50: 336779 | M50: 336972 | N50: 337195 | O50: 337448 | P50: 337731
A51: 06063 | B51: Balcarce | C51: 48609 | D51: 48632 | E51: 48664 | F51: 48693 | G51: 48717 | H51: 48736 | I51: 48751 | J51: 48765 | K51: 48782 | L51: 48803 | M51: 48829 | N51: 48859 | O51: 48893 | P51: 48931
A52: 06070 | B52: Baradero | C52: 39291 | D52: 39327 | E52: 39376 | F52: 39420 | G52: 39456 | H52: 39484 | I52: 39508 | J52: 39529 | K52: 39554 | L52: 39587 | M52: 39626 | N52: 39671 | O52: 39723 | P52: 39781
A53: 06077 | B53: Arrecifes | C53: 31982 | D53: 31996 | E53: 32016 | F53: 32036 | G53: 32052 | H53: 32064 | I53: 32074 | J53: 32084 | K53: 32095 | L53: 32109 | M53: 32126 | N53: 32146 | O53: 32167 | P53: 32191
A54: 06084 | B54: Benito Juárez | C54: 22161 | D54: 22171 | E54: 22185 | F54: 22199 | G54: 22210 | H54: 22219 | I54: 22228 | J54: 22235 | K54: 22244 | L54: 22255 | M54: 22267 | N54: 22280 | O54: 22295 | P54: 22313
A55: 06105 | B55: Bolívar | C55: 36886 | D55: 36896 | E55: 36912 | F55: 36925 | G55: 36935 | H55: 36943 | I55: 36948 | J55: 36954 | K55: 36961 | L55: 36969 | M55: 36980 | N55: 36994 | O55: 37009 | P55: 37027
A56: 06112 | B56: Bragado | C56: 46181 | D56: 46206 | E56: 46240 | F56: 46272 | G56: 46298 | H56: 46318 | I56: 46335 | J56: 46352 | K56: 46370 | L56: 46394 | M56: 46423 | N56: 46455 | O56: 46491 | P56: 46532
... A140: 06875 | B140: Villarino | C140: 32643 | D140: 32650 | E140: 32660 | F140: 32669 | G140: 32677 | H140: 32684 | I140: 32689 | J140: 32694 | K140: 32700 | L140: 32708 | M140: 32715 | N140: 32726 | O140: 32737 | P140: 32748
A142: Varones
A143: Código | B143: Partido | C143: 2022 | D143: 2023 | E143: 2024 | F143: 2025 | G143: 2026 | H143: 2027 | I143: 2028 | J143: 2029 | K143: 2030 | L143: 2031 | M143: 2032 | N143: 2033 | O143: 2034 | P143: 2035
A144: 39 partidos de la Región Metropolitana de Buenos Aires
A145: 06028 | B145: Almirante Brown | C145: 285832 | D145: 285902 | E145: 285999 | F145: 286097 | G145: 286184 | H145: 286260 | I145: 286329 | J145: 286396 | K145: 286468 | L145: 286551 | M145: 286643 | N145: 286745 | O145: 286855 | P145: 286975
A146: 06035 | B146: Avellaneda | C146: 176473 | D146: 176555 | E146: 176667 | F146: 176779 | G146: 176879 | H146: 176967 | I146: 177046 | J146: 177124 | K146: 177207 | L146: 177302 | M146: 177408 | N146: 177525 | O146: 177653 | P146: 177791
A147: 06091 | B147: Berazategui | C147: 175628 | D147: 175739 | E147: 175891 | F147: 176045 | G147: 176180 | H147: 176300 | I147: 176408 | J147: 176514 | K147: 176627 | L147: 176757 | M147: 176901 | N147: 177061 | O147: 177234 | P147: 177423
A148: 06098 | B148: Berisso | C148: 49839 | D148: 49888 | E148: 49954 | F148: 50021 | G148: 50081 | H148: 50133 | I148: 50180 | J148: 50226 | K148: 50276 | L148: 50333 | M148: 50396 | N148: 50466 | O148: 50542 | P148: 50624
A149: 06119 | B149: Brandsen | C149: 16302 | D149: 16326 | E149: 16361 | F149: 16395 | G149: 16426 | H149: 16453 | I149: 16477 | J149: 16501 | K149: 16526 | L149: 16555 | M149: 16588 | N149: 16624 | O149: 16663 | P149: 16705
A150: 06126 | B150: Campana | C150: 55449 | D150: 55508 | E150: 55590 | F150: 55672 | G150: 55745 | H150: 55809 | I150: 55867 | J150: 55924 | K150: 55985 | L150: 56054 | M150: 56132 | N150: 56217 | O150: 56310 | P150: 56411
...

Sheet 10-CATAMARCA
A1: Cuadro 3. Provincia de Catamarca. Población estimada al 1.° de julio de cada año calendario, por sexo, según departamento. Años 2022-2035
A2: Ambos sexos
A3: Código | B3: Departamento | C3: 2022 | D3: 2023 | E3: 2024 | F3: 2025 | G3: 2026 | H3: 2027 | I3: 2028 | J3: 2029 | K3: 2030 | L3: 2031 | M3: 2032 | N3: 2033 | O3: 2034 | P3: 2035
A4: 10007 | B4: Ambato | C4: 5195 | D4: 5208 | E4: 5222 | F4: 5237 | G4: 5252 | H4: 5266 | I4: 5280 | J4: 5294 | K4: 5307 | L4: 5319 | M4: 5332 | N4: 5345 | O4: 5357 | P4: 5369
A5: 10014 | B5: Ancasti | C5: 3349 | D5: 3356 | E5: 3364 | F5: 3372 | G5: 3379 | H5: 3388 | I5: 3394 | J5: 3401 | K5: 3408 | L5: 3415 | M5: 3422 | N5: 3429 | O5: 3435 | P5: 3442
A6: 10021 | B6: Andalgalá | C6: 19919 | D6: 19938 | E6: 19959 | F6: 19981 | G6: 20003 | H6: 20023 | I6: 20043 | J6: 20062 | K6: 20082 | L6: 20100 | M6: 20119 | N6: 20137 | O6: 20155 | P6: 20173
A7: 10028 | B7: Antofagasta de la Sierra | C7: 2052 | D7: 2068 | E7: 2085 | F7: 2103 | G7: 2121 | H7: 2137 | I7: 2154 | J7: 2170 | K7: 2185 | L7: 2201 | M7: 2217 | N7: 2231 | O7: 2247 | P7: 2261
A8: 10035 | B8: Belén | C8: 30942 | D8: 30982 | E8: 31024 | F8: 31073 | G8: 31118 | H8: 31163 | I8: 31207 | J8: 31248 | K8: 31290 | L8: 31330 | M8: 31370 | N8: 31412 | O8: 31450 | P8: 31489
A9: 10042 | B9: Capayán | C9: 20144 | D9: 20237 | E9: 20337 | F9: 20442 | G9: 20545 | H9: 20644 | I9: 20740 | J9: 20833 | K9: 20926 | L9: 21016 | M9: 21106 | N9: 21196 | O9: 21282 | P9: 21368
A10: 10049 | B10: Capital | C10: 189112 | D10: 189709 | E10: 190350 | F10: 191024 | G10: 191684 | H10: 192316 | I10: 192930 | J10: 193525 | K10: 194117 | L10: 194695 | M10: 195271 | N10: 195847 | O10: 196401 | P10: 196948
A11: 10056 | B11: El Alto | C11: 4431 | D11: 4450 | E11: 4470 | F11: 4493 | G11: 4513 | H11: 4534 | I11: 4554 | J11: 4574 | K11: 4592 | L11: 4610 | M11: 4630 | N11: 4648 | O11: 4667 | P11: 4683
A12: 10063 | B12: Fray Mamerto Esquiú | C12: 14806 | D12: 14872 | E12: 14943 | F12: 15018 | G12: 15091 | H12: 15160 | I12: 15229 | J12: 15295 | K12: 15360 | L12: 15424 | M12: 15488 | N12: 15552 | O12: 15613 | P12: 15674
A13: 10070 | B13: La Paz | C13: 26696 | D13: 26776 | E13: 26860 | F13: 26951 | G13: 27040 | H13: 27125 | I13: 27208 | J13: 27288 | K13: 27367 | L13: 27444 | M13: 27522 | N13: 27599 | O13: 27674 | P13: 27748
A14: 10077 | B14: Paclín | C14: 4787 | D14: 4797 | E14: 4807 | F14: 4818 | G14: 4829 | H14: 4839 | I14: 4850 | J14: 4860 | K14: 4869 | L14: 4879 | M14: 4889 | N14: 4898 | O14: 4907 | P14: 4916
... A19: 10112 | B19: Valle Viejo | C19: 34443 | D19: 34612 | E19: 34793 | F19: 34984 | G19: 35170 | H19: 35349 | I19: 35521 | J19: 35689 | K19: 35856 | L19: 36020 | M19: 36182 | N19: 36345 | O19: 36501 | P19: 36655
A21: Varones
A22: Código | B22: Departamento | C22: 2022 | D22: 2023 | E22: 2024 | F22: 2025 | G22: 2026 | H22: 2027 | I22: 2028 | J22: 2029 | K22: 2030 | L22: 2031 | M22: 2032 | N22: 2033 | O22: 2034 | P22: 2035
A23: 10007 | B23: Ambato | C23: 2691 | D23: 2697 | E23: 2703 | F23: 2709 | G23: 2715 | H23: 2721 | I23: 2727 | J23: 2733 | K23: 2738 | L23: 2743 | M23: 2748 | N23: 2754 | O23: 2759 | P23: 2764
A24: 10014 | B24: Ancasti | C24: 1821 | D24: 1825 | E24: 1830 | F24: 1834 | G24: 1838 | H24: 1843 | I24: 1846 | J24: 1850 | K24: 1854 | L24: 1858 | M24: 1862 | N24: 1866 | O24: 1869 | P24: 1873
A25: 10021 | B25: Andalgalá | C25: 10136 | D25: 10146 | E25: 10157 | F25: 10168 | G25: 10179 | H25: 10189 | I25: 10199 | J25: 10208 | K25: 10218 | L25: 10227 | M25: 10236 | N25: 10245 | O25: 10254 | P25: 10263
A26: 10028 | B26: Antofagasta de la Sierra | C26: 1154 | D26: 1163 | E26: 1172 | F26: 1181 | G26: 1190 | H26: 1198 | I26: 1206 | J26: 1214 | K26: 1222 | L26: 1230 | M26: 1238 | N26: 1245 | O26: 1253 | P26: 1260
A27: 10035 | B27: Belén | C27: 15537 | D27: 15544 | E27: 15551 | F27: 15559 | G27: 15566 | H27: 15573 | I27: 15580 | J27: 15586 | K27: 15593 | L27: 15599 | M27: 15605 | N27: 15612 | O27: 15618 | P27: 15624
A28: 10042 | B28: Capayán | C28: 10521 | D28: 10568 | E28: 10619 | F28: 10668 | G28: 10717 | H28: 10763 | I28: 10808 | J28: 10852 | K28: 10896 | L28: 10938 | M28: 10981 | N28: 11023 | O28: 11064 | P28: 11104
A29: 10049 | B29: Capital | C29: 92784 | D29: 93108 | E29: 93455 | F29: 93795 | G29: 94131 | H29: 94448 | I29: 94759 | J29: 95060 | K29: 95360 | L29: 95653 | M29: 95946 | N29: 96238 | O29: 96520 | P29: 96797
A30: 10056 | B30: El Alto | C30: 2306 | D30: 2314 | E30: 2323 | F30: 2332 | G30: 2340 | H30: 2348 | I30: 2356 | J30: 2364 | K30: 2371 | L30: 2378 | M30: 2386 | N30: 2393 | O30: 2401 | P30: 2407
A31: 10063 | B31: Fray Mamerto Esquiú | C31: 7486 | D31: 7521 | E31: 7559 | F31: 7596 | G31: 7632 | H31: 7666 | I31: 7700 | J31: 7733 | K31: 7765 | L31: 7797 | M31: 7829 | N31: 7860 | O31: 7891 | P31: 7921
A32: 10070 | B32: La Paz | C32: 13507 | D32: 13543 | E32: 13581 | F32: 13619 | G32: 13656 | H32: 13691 | I32: 13726 | J32: 13759 | K32: 13792 | L32: 13824 | M32: 13857 | N32: 13889 | O32: 13920 | P32: 13951
A33: 10077 | B33: Paclín | C33: 2512 | D33: 2516 | E33: 2519 | F33: 2523 | G33: 2527 | H33: 2530 | I33: 2534 | J33: 2537 | K33: 2540 | L33: 2543 | M33: 2547 | N33: 2550 | O33: 2553 | P33: 2556
... A38: 10112 | B38: Valle Viejo | C38: 17281 | D38: 17373 | E38: 17473 | F38: 17570 | G38: 17666 | H38: 17757 | I38: 17845 | J38: 17931 | K38: 18017 | L38: 18101 | M38: 18184 | N38: 18268 | O38: 18348 | P38: 18427
A40: Mujeres
A41: Código | B41: Departamento | C41: 2022 | D41: 2023 | E41: 2024 | F41: 2025 | G41: 2026 | H41: 2027 | I41: 2028 | J41: 2029 | K41: 2030 | L41: 2031 | M41: 2032 | N41: 2033 | O41: 2034 | P41: 2035
A42: 10007 | B42: Ambato | C42: 2504 | D42: 2511 | E42: 2519 | F42: 2528 | G42: 2537 | H42: 2545 | I42: 2553 | J42: 2561 | K42: 2569 | L42: 2576 | M42: 2584 | N42: 2591 | O42: 2598 | P42: 2605
A43: 10014 | B43: Ancasti | C43: 1528 | D43: 1531 | E43: 1534 | F43: 1538 | G43: 1541 | H43: 1545 | I43: 1548 | J43: 1551 | K43: 1554 | L43: 1557 | M43: 1560 | N43: 1563 | O43: 1566 | P43: 1569
A44: 10021 | B44: Andalgalá | C44: 9783 | D44: 9792 | E44: 9802 | F44: 9813 | G44: 9824 | H44: 9834 | I44: 9844 | J44: 9854 | K44: 9864 | L44: 9873 | M44: 9883 | N44: 9892 | O44: 9901 | P44: 9910
A45: 10028 | B45: Antofagasta de la Sierra | C45: 898 | D45: 905 | E45: 913 | F45: 922 | G45: 931 | H45: 939 | I45: 948 | J45: 956 | K45: 963 | L45: 971 | M45: 979 | N45: 986 | O45: 994 | P45: 1001
A46: 10035 | B46: Belén | C46: 15405 | D46: 15438 | E46: 15473 | F46: 15514 | G46: 15552 | H46: 15590 | I46: 15627 | J46: 15662 | K46: 15697 | L46: 15731 | M46: 15765 | N46: 15800 | O46: 15832 | P46: 15865
A47: 10042 | B47: Capayán | C47: 9623 | D47: 9669 | E47: 9718 | F47: 9774 | G47: 9828 | H47: 9881 | I47: 9932 | J47: 9981 | K47: 10030 | L47: 10078 | M47: 10125 | N47: 10173 | O47: 10218 | P47: 10264
A48: 10049 | B48: Capital | C48: 96328 | D48: 96601 | E48: 96895 | F48: 97229 | G48: 97553 | H48: 97868 | I48: 98171 | J48: 98465 | K48: 98757 | L48: 99042 | M48: 99325 | N48: 99609 | O48: 99881 | P48: 100151
A49: 10056 | B49: El Alto | C49: 2125 | D49: 2136 | E49: 2147 | F49: 2161 | G49: 2173 | H49: 2186 | I49: 2198 | J49: 2210 | K49: 2221 | L49: 2232 | M49: 2244 | N49: 2255 | O49: 2266 | P49: 2276
A50: 10063 | B50: Fray Mamerto Esquiú | C50: 7320 | D50: 7351 | E50: 7384 | F50: 7422 | G50: 7459 | H50: 7494 | I50: 7529 | J50: 7562 | K50: 7595 | L50: 7627 | M50: 7659 | N50: 7692 | O50: 7722 | P50: 7753
...

Sheet 14-CÓRDOBA
A1: Cuadro 4. Provincia de Córdoba. Población estimada al 1.° de julio de cada año calendario, por sexo, según departamento. Años 2022-2035
A2: Ambos sexos
A3: Código | B3: Departamento | C3: 2022 | D3: 2023 | E3: 2024 | F3: 2025 | G3: 2026 | H3: 2027 | I3: 2028 | J3: 2029 | K3: 2030 | L3: 2031 | M3: 2032 | N3: 2033 | O3: 2034 | P3: 2035
A4: 14007 | B4: Calamuchita | C4: 77568 | D4: 78136 | E4: 78730 | F4: 79298 | G4: 79840 | H4: 80356 | I4: 80850 | J4: 81327 | K4: 81802 | L4: 82284 | M4: 82773 | N4: 83265 | O4: 83761 | P4: 84259
A5: 14014 | B5: Capital | C5: 1537085 | D5: 1540015 | E5: 1543077 | F5: 1546009 | G5: 1548809 | H5: 1551469 | I5: 1554016 | J5: 1556479 | K5: 1558936 | L5: 1561424 | M5: 1563946 | N5: 1566489 | O5: 1569046 | P5: 1571625
A6: 14021 | B6: Colón | C6: 302112 | D6: 303930 | E6: 305830 | F6: 307650 | G6: 309386 | H6: 311036 | I6: 312615 | J6: 314143 | K6: 315666 | L6: 317209 | M6: 318773 | N6: 320350 | O6: 321935 | P6: 323532
A7: 14028 | B7: Cruz del Eje | C7: 68592 | D7: 68795 | E7: 69006 | F7: 69209 | G7: 69403 | H7: 69587 | I7: 69764 | J7: 69936 | K7: 70107 | L7: 70279 | M7: 70455 | N7: 70633 | O7: 70811 | P7: 70991
A8: 14035 | B8: General Roca | C8: 37043 | D8: 37016 | E8: 36987 | F8: 36960 | G8: 36934 | H8: 36910 | I8: 36885 | J8: 36864 | K8: 36841 | L8: 36818 | M8: 36794 | N8: 36771 | O8: 36748 | P8: 36724
A9: 14042 | B9: General San Martín | C9: 157598 | D9: 158263 | E9: 158958 | F9: 159623 | G9: 160258 | H9: 160862 | I9: 161439 | J9: 161998 | K9: 162556 | L9: 163121 | M9: 163692 | N9: 164270 | O9: 164850 | P9: 165436
A10: 14049 | B10: Ischilín | C10: 36850 | D10: 36929 | E10: 37011 | F10: 37090 | G10: 37165 | H10: 37237 | I10: 37305 | J10: 37372 | K10: 37437 | L10: 37504 | M10: 37573 | N10: 37641 | O10: 37710 | P10: 37779
A11: 14056 | B11: Juárez Celman | C11: 70128 | D11: 70303 | E11: 70485 | F11: 70659 | G11: 70825 | H11: 70983 | I11: 71135 | J11: 71281 | K11: 71428 | L11: 71575 | M11: 71725 | N11: 71876 | O11: 72029 | P11: 72182
A12: 14063 | B12: Marcos Juárez | C12: 110091 | D12: 110071 | E12: 110049 | F12: 110027 | G12: 110008 | H12: 109990 | I12: 109972 | J12: 109956 | K12: 109939 | L12: 109921 | M12: 109905 | N12: 109887 | O12: 109870 | P12: 109853
A13: 14070 | B13: Minas | C13: 4978 | D13: 4972 | E13: 4967 | F13: 4961 | G13: 4956 | H13: 4951 | I13: 4946 | J13: 4941 | K13: 4937 | L13: 4932 | M13: 4927 | N13: 4922 | O13: 4917 | P13: 4913
A14: 14077 | B14: Pocho | C14: 5237 | D14: 5223 | E14: 5210 | F14: 5197 | G14: 5184 | H14: 5172 | I14: 5160 | J14: 5149 | K14: 5138 | L14: 5126 | M14: 5115 | N14: 5104 | O14: 5093 | P14: 5080
... A29: 14182 | B29: Unión | C29: 117065 | D29: 117200 | E29: 117340 | F29: 117475 | G29: 117606 | H29: 117728 | I29: 117846 | J29: 117959 | K29: 118073 | L29: 118188 | M29: 118304 | N29: 118423 | O29: 118541 | P29: 118661
A31: Varones
A32: Código | B32: Departamento | C32: 2022 | D32: 2023 | E32: 2024 | F32: 2025 | G32: 2026 | H32: 2027 | I32: 2028 | J32: 2029 | K32: 2030 | L32: 2031 | M32: 2032 | N32: 2033 | O32: 2034 | P32: 2035
A33: 14007 | B33: Calamuchita | C33: 38962 | D33: 39252 | E33: 39552 | F33: 39845 | G33: 40127 | H33: 40397 | I33: 40658 | J33: 40911 | K33: 41164 | L33: 41421 | M33: 41683 | N33: 41947 | O33: 42213 | P33: 42481
A34: 14014 | B34: Capital | C34: 743340 | D34: 744866 | E34: 746442 | F34: 747981 | G34: 749463 | H34: 750883 | I34: 752250 | J34: 753580 | K34: 754912 | L34: 756263 | M34: 757636 | N34: 759024 | O34: 760420 | P34: 761832
A35: 14021 | B35: Colón | C35: 149618 | D35: 150550 | E35: 151513 | F35: 152454 | G35: 153359 | H35: 154227 | I35: 155062 | J35: 155875 | K35: 156688 | L35: 157514 | M35: 158353 | N35: 159201 | O35: 160054 | P35: 160916
A36: 14028 | B36: Cruz del Eje | C36: 34921 | D36: 35046 | E36: 35175 | F36: 35301 | G36: 35422 | H36: 35538 | I36: 35650 | J36: 35759 | K36: 35868 | L36: 35978 | M36: 36090 | N36: 36204 | O36: 36318 | P36: 36434
A37: 14035 | B37: General Roca | C37: 18920 | D37: 18909 | E37: 18897 | F37: 18886 | G37: 18875 | H37: 18865 | I37: 18854 | J37: 18845 | K37: 18835 | L37: 18825 | M37: 18815 | N37: 18805 | O37: 18795 | P37: 18784
A38: 14042 | B38: General San Martín | C38: 78111 | D38: 78460 | E38: 78820 | F38: 79171 | G38: 79510 | H38: 79834 | I38: 80146 | J38: 80450 | K38: 80754 | L38: 81063 | M38: 81376 | N38: 81693 | O38: 82012 | P38: 82335
A39: 14049 | B39: Ischilín | C39: 18156 | D39: 18199 | E39: 18243 | F39: 18286 | G39: 18328 | H39: 18368 | I39: 18406 | J39: 18444 | K39: 18481 | L39: 18519 | M39: 18558 | N39: 18597 | O39: 18636 | P39: 18675
A40: 14056 | B40: Juárez Celman | C40: 35194 | D40: 35284 | E40: 35377 | F40: 35468 | G40: 35555 | H40: 35639 | I40: 35720 | J40: 35798 | K40: 35877 | L40: 35956 | M40: 36037 | N40: 36119 | O40: 36202 | P40: 36285
A41: 14063 | B41: Marcos Juárez | C41: 54505 | D41: 54504 | E41: 54502 | F41: 54500 | G41: 54499 | H41: 54498 | I41: 54496 | J41: 54495 | K41: 54494 | L41: 54492 | M41: 54491 | N41: 54489 | O41: 54488 | P41: 54487
A42: 14070 | B42: Minas | C42: 2568 | D42: 2564 | E42: 2561 | F42: 2557 | G42: 2554 | H42: 2550 | I42: 2547 | J42: 2544 | K42: 2541 | L42: 2538 | M42: 2534 | N42: 2531 | O42: 2528 | P42: 2525
A43: 14077 | B43: Pocho | C43: 2688 | D43: 2680 | E43: 2673 | F43: 2665 | G43: 2657 | H43: 2650 | I43: 2643 | J43: 2637 | K43: 2630 | L43: 2623 | M43: 2616 | N43: 2610 | O43: 2603 | P43: 2595
... A58: 14182 | B58: Unión | C58: 58580 | D58: 58658 | E58: 58739 | F58: 58818 | G58: 58895 | H58: 58968 | I58: 59038 | J58: 59106 | K58: 59174 | L58: 59244 | M58: 59314 | N58: 59386 | O58: 59457 | P58: 59530
A60: Mujeres
A61: Código | B61: Departamento | C61: 2022 | D61: 2023 | E61: 2024 | F61: 2025 | G61: 2026 | H61: 2027 | I61: 2028 | J61: 2029 | K61: 2030 | L61: 2031 | M61: 2032 | N61: 2033 | O61: 2034 | P61: 2035
A62: 14007 | B62: Calamuchita | C62: 38606 | D62: 38884 | E62: 39178 | F62: 39453 | G62: 39713 | H62: 39959 | I62: 40192 | J62: 40416 | K62: 40638 | L62: 40863 | M62: 41090 | N62: 41318 | O62: 41548 | P62: 41778
A63: 14014 | B63: Capital | C63: 793745 | D63: 795149 | E63: 796635 | F63: 798028 | G63: 799346 | H63: 800586 | I63: 801766 | J63: 802899 | K63: 804024 | L63: 805161 | M63: 806310 | N63: 807465 | O63: 808626 | P63: 809793
A64: 14021 | B64: Colón | C64: 152494 | D64: 153380 | E64: 154317 | F64: 155196 | G64: 156027 | H64: 156809 | I64: 157553 | J64: 158268 | K64: 158978 | L64: 159695 | M64: 160420 | N64: 161149 | O64: 161881 | P64: 162616
A65: 14028 | B65: Cruz del Eje | C65: 33671 | D65: 33749 | E65: 33831 | F65: 33908 | G65: 33981 | H65: 34049 | I65: 34114 | J65: 34177 | K65: 34239 | L65: 34301 | M65: 34365 | N65: 34429 | O65: 34493 | P65: 34557
A66: 14035 | B66: General Roca | C66: 18123 | D66: 18107 | E66: 18090 | F66: 18074 | G66: 18059 | H66: 18045 | I66: 18031 | J66: 18019 | K66: 18006 | L66: 17993 | M66: 17979 | N66: 17966 | O66: 17953 | P66: 17940
A67: 14042 | B67: General San Martín | C67: 79487 | D67: 79803 | E67: 80138 | F67: 80452 | G67: 80748 | H67: 81028 | I67: 81293 | J67: 81548 | K67: 81802 | L67: 82058 | M67: 82316 | N67: 82577 | O67: 82838 | P67: 83101
A68: 14049 | B68: Ischilín | C68: 18694 | D68: 18730 | E68: 18768 | F68: 18804 | G68: 18837 | H68: 18869 | I68: 18899 | J68: 18928 | K68: 18956 | L68: 18985 | M68: 19015 | N68: 19044 | O68: 19074 | P68: 19104
A69: 14056 | B69: Juárez Celman | C69: 34934 | D69: 35019 | E69: 35108 | F69: 35191 | G69: 35270 | H69: 35344 | I69: 35415 | J69: 35483 | K69: 35551 | L69: 35619 | M69: 35688 | N69: 35757 | O69: 35827 | P69: 35897
A70: 14063 | B70: Marcos Juárez | C70: 55586 | D70: 55567 | E70: 55547 | F70: 55527 | G70: 55509 | H70: 55492 | I70: 55476 | J70: 55461 | K70: 55445 | L70: 55429 | M70: 55414 | N70: 55398 | O70: 55382 | P70: 55366
...

Sheet 18-CORRIENTES
A1: Cuadro 5. Provincia de Corrientes. Población estimada al 1.° de julio de cada año calendario, por sexo, según departamento. Años 2022-2035
A2: Ambos sexos
A3: Código | B3: Departamento | C3: 2022 | D3: 2023 | E3: 2024 | F3: 2025 | G3: 2026 | H3: 2027 | I3: 2028 | J3: 2029 | K3: 2030 | L3: 2031 | M3: 2032 | N3: 2033 | O3: 2034 | P3: 2035
A4: 18007 | B4: Bella Vista | C4: 43550 | D4: 43696 | E4: 43849 | F4: 43989 | G4: 44121 | H4: 44240 | I4: 44356 | J4: 44472 | K4: 44586 | L4: 44699 | M4: 44813 | N4: 44925 | O4: 45036 | P4: 45145
A5: 18014 | B5: Berón de Astrada | C5: 2774 | D5: 2780 | E5: 2785 | F5: 2790 | G5: 2795 | H5: 2800 | I5: 2804 | J5: 2808 | K5: 2813 | L5: 2817 | M5: 2821 | N5: 2826 | O5: 2830 | P5: 2834
A6: 18021 | B6: Capital | C6: 430534 | D6: 432388 | E6: 434317 | F6: 436111 | G6: 437771 | H6: 439291 | I6: 440763 | J6: 442236 | K6: 443682 | L6: 445124 | M6: 446565 | N6: 447996 | O6: 449400 | P6: 450796
A7: 18028 | B7: Concepción | C7: 25785 | D7: 25913 | E7: 26045 | F7: 26167 | G7: 26280 | H7: 26384 | I7: 26485 | J7: 26585 | K7: 26683 | L7: 26781 | M7: 26879 | N7: 26977 | O7: 27072 | P7: 27166
A8: 18035 | B8: Curuzú Cuatiá | C8: 50527 | D8: 50645 | E8: 50769 | F8: 50884 | G8: 50990 | H8: 51087 | I8: 51181 | J8: 51276 | K8: 51367 | L8: 51460 | M8: 51552 | N8: 51644 | O8: 51734 | P8: 51823
A9: 18042 | B9: Empedrado | C9: 17623 | D9: 17679 | E9: 17737 | F9: 17791 | G9: 17841 | H9: 17886 | I9: 17931 | J9: 17975 | K9: 18019 | L9: 18062 | M9: 18105 | N9: 18149 | O9: 18191 | P9: 18234
A10: 18049 | B10: Esquina | C10: 38419 | D10: 38631 | E10: 38849 | F10: 39052 | G10: 39240 | H10: 39412 | I10: 39579 | J10: 39745 | K10: 39908 | L10: 40072 | M10: 40235 | N10: 40396 | O10: 40555 | P10: 40712
A11: 18056 | B11: General Alvear | C11: 8975 | D11: 8993 | E11: 9011 | F11: 9028 | G11: 9045 | H11: 9060 | I11: 9074 | J11: 9089 | K11: 9102 | L11: 9117 | M11: 9131 | N11: 9146 | O11: 9159 | P11: 9173
A12: 18063 | B12: General Paz | C12: 16696 | D12: 16726 | E12: 16759 | F12: 16788 | G12: 16816 | H12: 16840 | I12: 16864 | J12: 16889 | K12: 16913 | L12: 16937 | M12: 16961 | N12: 16983 | O12: 17006 | P12: 17030
A13: 18070 | B13: Goya | C13: 104277 | D13: 104585 | E13: 104906 | F13: 105205 | G13: 105482 | H13: 105736 | I13: 105981 | J13: 106227 | K13: 106468 | L13: 106708 | M13: 106949 | N13: 107188 | O13: 107422 | P13: 107654
A14: 18077 | B14: Itatí | C14: 11776 | D14: 11852 | E14: 11931 | F14: 12004 | G14: 12073 | H14: 12135 | I14: 12195 | J14: 12256 | K14: 12316 | L14: 12375 | M14: 12433 | N14: 12492 | O14: 12550 | P14: 12607
... A28: 18175 | B28: Sauce | C28: 10183 | D28: 10202 | E28: 10222 | F28: 10240 | G28: 10258 | H28: 10273 | I28: 10288 | J28: 10304 | K28: 10318 | L28: 10333 | M28: 10349 | N28: 10364 | O28: 10378 | P28: 10393
A30: Varones
A31: Código | B31: Departamento | C31: 2022 | D31: 2023 | E31: 2024 | F31: 2025 | G31: 2026 | H31: 2027 | I31: 2028 | J31: 2029 | K31: 2030 | L31: 2031 | M31: 2032 | N31: 2033 | O31: 2034 | P31: 2035
A32: 18007 | B32: Bella Vista | C32: 21929 | D32: 21996 | E32: 22069 | F32: 22137 | G32: 22202 | H32: 22260 | I32: 22317 | J32: 22375 | K32: 22432 | L32: 22488 | M32: 22545 | N32: 22601 | O32: 22657 | P32: 22712
A33: 18014 | B33: Berón de Astrada | C33: 1444 | D33: 1447 | E33: 1450 | F33: 1452 | G33: 1455 | H33: 1458 | I33: 1460 | J33: 1462 | K33: 1465 | L33: 1467 | M33: 1469 | N33: 1472 | O33: 1474 | P33: 1476
A34: 18021 | B34: Capital | C34: 210657 | D34: 211559 | E34: 212525 | F34: 213442 | G34: 214297 | H34: 215083 | I34: 215847 | J34: 216615 | K34: 217372 | L34: 218129 | M34: 218886 | N34: 219640 | O34: 220384 | P34: 221125
A35: 18028 | B35: Concepción | C35: 13195 | D35: 13247 | E35: 13303 | F35: 13356 | G35: 13405 | H35: 13451 | I35: 13495 | J35: 13539 | K35: 13583 | L35: 13626 | M35: 13670 | N35: 13714 | O35: 13757 | P35: 13799
A36: 18035 | B36: Curuzú Cuatiá | C36: 25070 | D36: 25128 | E36: 25191 | F36: 25250 | G36: 25305 | H36: 25356 | I36: 25405 | J36: 25455 | K36: 25503 | L36: 25552 | M36: 25601 | N36: 25650 | O36: 25698 | P36: 25746
A37: 18042 | B37: Empedrado | C37: 8878 | D37: 8906 | E37: 8935 | F37: 8963 | G37: 8989 | H37: 9013 | I37: 9037 | J37: 9060 | K37: 9083 | L37: 9106 | M37: 9129 | N37: 9152 | O37: 9175 | P37: 9198
A38: 18049 | B38: Esquina | C38: 19029 | D38: 19124 | E38: 19225 | F38: 19321 | G38: 19410 | H38: 19493 | I38: 19573 | J38: 19653 | K38: 19732 | L38: 19812 | M38: 19891 | N38: 19970 | O38: 20048 | P38: 20125
A39: 18056 | B39: General Alvear | C39: 4625 | D39: 4638 | E39: 4651 | F39: 4664 | G39: 4677 | H39: 4688 | I39: 4699 | J39: 4710 | K39: 4720 | L39: 4731 | M39: 4742 | N39: 4753 | O39: 4763 | P39: 4774
A40: 18063 | B40: General Paz | C40: 8458 | D40: 8472 | E40: 8488 | F40: 8502 | G40: 8516 | H40: 8528 | I40: 8540 | J40: 8553 | K40: 8565 | L40: 8577 | M40: 8589 | N40: 8600 | O40: 8612 | P40: 8624
A41: 18070 | B41: Goya | C41: 51341 | D41: 51494 | E41: 51659 | F41: 51816 | G41: 51962 | H41: 52097 | I41: 52227 | J41: 52359 | K41: 52488 | L41: 52617 | M41: 52747 | N41: 52876 | O41: 53003 | P41: 53129
A42: 18077 | B42: Itatí | C42: 5982 | D42: 6021 | E42: 6062 | F42: 6101 | G42: 6138 | H42: 6171 | I42: 6204 | J42: 6237 | K42: 6270 | L42: 6302 | M42: 6334 | N42: 6366 | O42: 6398 | P42: 6430
... A56: 18175 | B56: Sauce | C56: 5132 | D56: 5144 | E56: 5156 | F56: 5168 | G56: 5179 | H56: 5189 | I56: 5199 | J56: 5209 | K56: 5218 | L56: 5228 | M56: 5238 | N56: 5248 | O56: 5257 | P56: 5267
A58: Mujeres
A59: Código | B59: Departamento | C59: 2022 | D59: 2023 | E59: 2024 | F59: 2025 | G59: 2026 | H59: 2027 | I59: 2028 | J59: 2029 | K59: 2030 | L59: 2031 | M59: 2032 | N59: 2033 | O59: 2034 | P59: 2035
A60: 18007 | B60: Bella Vista | C60: 21621 | D60: 21700 | E60: 21780 | F60: 21852 | G60: 21919 | H60: 21980 | I60: 22039 | J60: 22097 | K60: 22154 | L60: 22211 | M60: 22268 | N60: 22324 | O60: 22379 | P60: 22433
A61: 18014 | B61: Berón de Astrada | C61: 1330 | D61: 1333 | E61: 1335 | F61: 1338 | G61: 1340 | H61: 1342 | I61: 1344 | J61: 1346 | K61: 1348 | L61: 1350 | M61: 1352 | N61: 1354 | O61: 1356 | P61: 1358
A62: 18021 | B62: Capital | C62: 219877 | D62: 220829 | E62: 221792 | F62: 222669 | G62: 223474 | H62: 224208 | I62: 224916 | J62: 225621 | K62: 226310 | L62: 226995 | M62: 227679 | N62: 228356 | O62: 229016 | P62: 229671
A63: 18028 | B63: Concepción | C63: 12590 | D63: 12666 | E63: 12742 | F63: 12811 | G63: 12875 | H63: 12933 | I63: 12990 | J63: 13046 | K63: 13100 | L63: 13155 | M63: 13209 | N63: 13263 | O63: 13315 | P63: 13367
A64: 18035 | B64: Curuzú Cuatiá | C64: 25457 | D64: 25517 | E64: 25578 | F64: 25634 | G64: 25685 | H64: 25731 | I64: 25776 | J64: 25821 | K64: 25864 | L64: 25908 | M64: 25951 | N64: 25994 | O64: 26036 | P64: 26077
A65: 18042 | B65: Empedrado | C65: 8745 | D65: 8773 | E65: 8802 | F65: 8828 | G65: 8852 | H65: 8873 | I65: 8894 | J65: 8915 | K65: 8936 | L65: 8956 | M65: 8976 | N65: 8997 | O65: 9016 | P65: 9036
A66: 18049 | B66: Esquina | C66: 19390 | D66: 19507 | E66: 19624 | F66: 19731 | G66: 19830 | H66: 19919 | I66: 20006 | J66: 20092 | K66: 20176 | L66: 20260 | M66: 20344 | N66: 20426 | O66: 20507 | P66: 20587
A67: 18056 | B67: General Alvear | C67: 4350 | D67: 4355 | E67: 4360 | F67: 4364 | G67: 4368 | H67: 4372 | I67: 4375 | J67: 4379 | K67: 4382 | L67: 4386 | M67: 4389 | N67: 4393 | O67: 4396 | P67: 4399
A68: 18063 | B68: General Paz | C68: 8238 | D68: 8254 | E68: 8271 | F68: 8286 | G68: 8300 | H68: 8312 | I68: 8324 | J68: 8336 | K68: 8348 | L68: 8360 | M68: 8372 | N68: 8383 | O68: 8394 | P68: 8406
...

Sheet 22-CHACO
A1: Cuadro 6. Provincia del Chaco. Población estimada al 1.° de julio de cada año calendario, por sexo, según departamento. Años 2022-2035
A2: Ambos sexos
A3: Código | B3: Departamento | C3: 2022 | D3: 2023 | E3: 2024 | F3: 2025 | G3: 2026 | H3: 2027 | I3: 2028 | J3: 2029 | K3: 2030 | L3: 2031 | M3: 2032 | N3: 2033 | O3: 2034 | P3: 2035
A4: 22007 | B4: Almirante Brown | C4: 39920 | D4: 40113 | E4: 40423 | F4: 40757 | G4: 41088 | H4: 41412 | I4: 41731 | J4: 42040 | K4: 42337 | L4: 42628 | M4: 42913 | N4: 43190 | O4: 43462 | P4: 43726
A5: 22014 | B5: Bermejo | C5: 29678 | D5: 29829 | E5: 30070 | F5: 30334 | G5: 30592 | H5: 30846 | I5: 31096 | J5: 31338 | K5: 31571 | L5: 31799 | M5: 32023 | N5: 32239 | O5: 32452 | P5: 32660
A6: 22028 | B6: Chacabuco | C6: 36476 | D6: 36674 | E6: 36991 | F6: 37335 | G6: 37676 | H6: 38010 | I6: 38339 | J6: 38657 | K6: 38964 | L6: 39264 | M6: 39558 | N6: 39842 | O6: 40123 | P6: 40396
A7: 22021 | B7: Comandante Fernández | C7: 108417 | D7: 108738 | E7: 109252 | F7: 109809 | G7: 110360 | H7: 110899 | I7: 111429 | J7: 111945 | K7: 112438 | L7: 112923 | M7: 113398 | N7: 113858 | O7: 114309 | P7: 114750
A8: 22036 | B8: 12 de Octubre | C8: 24492 | D8: 24547 | E8: 24636 | F8: 24732 | G8: 24827 | H8: 24919 | I8: 25011 | J8: 25100 | K8: 25184 | L8: 25268 | M8: 25349 | N8: 25428 | O8: 25506 | P8: 25582
A9: 22039 | B9: 2 de Abril | C9: 8774 | D9: 8815 | E9: 8881 | F9: 8953 | G9: 9023 | H9: 9092 | I9: 9161 | J9: 9226 | K9: 9290 | L9: 9352 | M9: 9413 | N9: 9472 | O9: 9530 | P9: 9587
A10: 22043 | B10: Fray Justo Santa María de Oro | C10: 11233 | D10: 11188 | E10: 11114 | F10: 11035 | G10: 10956 | H10: 10877 | I10: 10802 | J10: 10728 | K10: 10657 | L10: 10586 | M10: 10518 | N10: 10451 | O10: 10387 | P10: 10323
A11: 22049 | B11: General Belgrano | C11: 13506 | D11: 13551 | E11: 13622 | F11: 13700 | G11: 13776 | H11: 13851 | I11: 13925 | J11: 13997 | K11: 14065 | L11: 14134 | M11: 14199 | N11: 14264 | O11: 14327 | P11: 14388
A12: 22056 | B12: General Donovan | C12: 15782 | D12: 15854 | E12: 15969 | F12: 16094 | G12: 16218 | H12: 16339 | I12: 16458 | J12: 16573 | K12: 16684 | L12: 16793 | M12: 16899 | N12: 17002 | O12: 17104 | P12: 17203
A13: 22063 | B13: General Güemes | C13: 70758 | D13: 70793 | E13: 70847 | F13: 70906 | G13: 70963 | H13: 71020 | I13: 71075 | J13: 71128 | K13: 71178 | L13: 71229 | M13: 71278 | N13: 71325 | O13: 71371 | P13: 71416
A14: 22070 | B14: Independencia | C14: 23187 | D14: 23181 | E14: 23169 | F14: 23157 | G14: 23143 | H14: 23131 | I14: 23118 | J14: 23106 | K14: 23095 | L14: 23082 | M14: 23071 | N14: 23060 | O14: 23049 | P14: 23038
A15: 22077 | B15: Libertad | C15: 15077 | D15: 15180 | E15: 15347 | F15: 15527 | G15: 15706 | H15: 15880 | I15: 16052 | J15: 16218 | K15: 16378 | L15: 16536 | M15: 16689 | N15: 16838 | O15: 16985 | P15: 17127
... A28: 22168 | B28: 25 De Mayo | C28: 34585 | D28: 34759 | E28: 35041 | F28: 35345 | G28: 35646 | H28: 35941 | I28: 36230 | J28: 36512 | K28: 36783 | L28: 37048 | M28: 37308 | N28: 37559 | O28: 37806 | P28: 38047
A30: Varones
A31: Código | B31: Departamento | C31: 2022 | D31: 2023 | E31: 2024 | F31: 2025 | G31: 2026 | H31: 2027 | I31: 2028 | J31: 2029 | K31: 2030 | L31: 2031 | M31: 2032 | N31: 2033 | O31: 2034 | P31: 2035
A32: 22007 | B32: Almirante Brown | C32: 20173 | D32: 20257 | E32: 20398 | F32: 20553 | G32: 20707 | H32: 20858 | I32: 21007 | J32: 21152 | K32: 21291 | L32: 21428 | M32: 21562 | N32: 21693 | O32: 21822 | P32: 21947
A33: 22014 | B33: Bermejo | C33: 14883 | D33: 14954 | E33: 15072 | F33: 15204 | G33: 15333 | H33: 15461 | I33: 15586 | J33: 15708 | K33: 15826 | L33: 15941 | M33: 16054 | N33: 16164 | O33: 16273 | P33: 16379
A34: 22028 | B34: Chacabuco | C34: 18094 | D34: 18195 | E34: 18362 | F34: 18547 | G34: 18731 | H34: 18911 | I34: 19089 | J34: 19262 | K34: 19428 | L34: 19591 | M34: 19751 | N34: 19906 | O34: 20060 | P34: 20210
A35: 22021 | B35: Comandante Fernández | C35: 52792 | D35: 52937 | E35: 53179 | F35: 53446 | G35: 53712 | H35: 53972 | I35: 54228 | J35: 54478 | K35: 54717 | L35: 54953 | M35: 55184 | N35: 55409 | O35: 55630 | P35: 55847
A36: 22036 | B36: 12 de Octubre | C36: 12372 | D36: 12396 | E36: 12436 | F36: 12480 | G36: 12524 | H36: 12566 | I36: 12609 | J36: 12650 | K36: 12689 | L36: 12728 | M36: 12766 | N36: 12803 | O36: 12840 | P36: 12875
A37: 22039 | B37: 2 de Abril | C37: 4443 | D37: 4462 | E37: 4494 | F37: 4530 | G37: 4565 | H37: 4600 | I37: 4634 | J37: 4667 | K37: 4699 | L37: 4730 | M37: 4761 | N37: 4791 | O37: 4820 | P37: 4849
A38: 22043 | B38: Fray Justo Santa María de Oro | C38: 5711 | D38: 5683 | E38: 5636 | F38: 5585 | G38: 5534 | H38: 5483 | I38: 5434 | J38: 5386 | K38: 5340 | L38: 5294 | M38: 5250 | N38: 5206 | O38: 5164 | P38: 5122
A39: 22049 | B39: General Belgrano | C39: 6812 | D39: 6834 | E39: 6870 | F39: 6910 | G39: 6949 | H39: 6988 | I39: 7026 | J39: 7064 | K39: 7099 | L39: 7135 | M39: 7169 | N39: 7203 | O39: 7236 | P39: 7268
A40: 22056 | B40: General Donovan | C40: 7959 | D40: 7992 | E40: 8046 | F40: 8107 | G40: 8167 | H40: 8226 | I40: 8284 | J40: 8340 | K40: 8394 | L40: 8447 | M40: 8499 | N40: 8550 | O40: 8600 | P40: 8649
A41: 22063 | B41: General Güemes | C41: 35764 | D41: 35764 | E41: 35764 | F41: 35765 | G41: 35765 | H41: 35766 | I41: 35766 | J41: 35766 | K41: 35766 | L41: 35767 | M41: 35767 | N41: 35767 | O41: 35768 | P41: 35768
A42: 22070 | B42: Independencia | C42: 11410 | D42: 11396 | E42: 11373 | F42: 11348 | G42: 11322 | H42: 11298 | I42: 11273 | J42: 11249 | K42: 11227 | L42: 11204 | M42: 11182 | N42: 11161 | O42: 11140 | P42: 11119
A43: 22077 | B43: Libertad | C43: 7545 | D43: 7594 | E43: 7676 | F43: 7766 | G43: 7856 | H43: 7944 | I43: 8031 | J43: 8115 | K43: 8196 | L43: 8276 | M43: 8354 | N43: 8430 | O43: 8505 | P43: 8578
... A56: 22168 | B56: 25 De Mayo | C56: 17460 | D56: 17544 | E56: 17685 | F56: 17840 | G56: 17994 | H56: 18146 | I56: 18294 | J56: 18439 | K56: 18579 | L56: 18716 | M56: 18850 | N56: 18980 | O56: 19109 | P56: 19235
A58: Mujeres
A59: Código | B59: Departamento | C59: 2022 | D59: 2023 | E59: 2024 | F59: 2025 | G59: 2026 | H59: 2027 | I59: 2028 | J59: 2029 | K59: 2030 | L59: 2031 | M59: 2032 | N59: 2033 | O59: 2034 | P59: 2035
A60: 22007 | B60: Almirante Brown | C60: 19747 | D60: 19856 | E60: 20025 | F60: 20204 | G60: 20381 | H60: 20554 | I60: 20724 | J60: 20888 | K60: 21046 | L60: 21200 | M60: 21351 | N60: 21497 | O60: 21640 | P60: 21779
A61: 22014 | B61: Bermejo | C61: 14795 | D61: 14875 | E61: 14998 | F61: 15130 | G61: 15259 | H61: 15385 | I61: 15510 | J61: 15630 | K61: 15745 | L61: 15858 | M61: 15969 | N61: 16075 | O61: 16179 | P61: 16281
A62: 22028 | B62: Chacabuco | C62: 18382 | D62: 18479 | E62: 18629 | F62: 18788 | G62: 18945 | H62: 19099 | I62: 19250 | J62: 19395 | K62: 19536 | L62: 19673 | M62: 19807 | N62: 19936 | O62: 20063 | P62: 20186
A63: 22021 | B63: Comandante Fernández | C63: 55625 | D63: 55801 | E63: 56073 | F63: 56363 | G63: 56648 | H63: 56927 | I63: 57201 | J63: 57467 | K63: 57721 | L63: 57970 | M63: 58214 | N63: 58449 | O63: 58679 | P63: 58903
A64: 22036 | B64: 12 de Octubre | C64: 12120 | D64: 12151 | E64: 12200 | F64: 12252 | G64: 12303 | H64: 12353 | I64: 12402 | J64: 12450 | K64: 12495 | L64: 12540 | M64: 12583 | N64: 12625 | O64: 12666 | P64: 12707
A65: 22039 | B65: 2 de Abril | C65: 4331 | D65: 4353 | E65: 4387 | F65: 4423 | G65: 4458 | H65: 4492 | I65: 4527 | J65: 4559 | K65: 4591 | L65: 4622 | M65: 4652 | N65: 4681 | O65: 4710 | P65: 4738
A66: 22043 | B66: Fray Justo Santa María de Oro | C66: 5522 | D66: 5505 | E66: 5478 | F66: 5450 | G66: 5422 | H66: 5394 | I66: 5368 | J66: 5342 | K66: 5317 | L66: 5292 | M66: 5268 | N66: 5245 | O66: 5223 | P66: 5201
...

Sheet 26-CHUBUT
A1: Cuadro 7. Provincia del Chubut. Población estimada al 1.° de julio de cada año calendario, por sexo, según departamento. Años 2022-2035
A2: Ambos sexos
A3: Código | B3: Departamento | C3: 2022 | D3: 2023 | E3: 2024 | F3: 2025 | G3: 2026 | H3: 2027 | I3: 2028 | J3: 2029 | K3: 2030 | L3: 2031 | M3: 2032 | N3: 2033 | O3: 2034 | P3: 2035
A4: 26007 | B4: Biedma | C4: 103970 | D4: 104368 | E4: 104802 | F4: 105222 | G4: 105618 | H4: 106000 | I4: 106367 | J4: 106721 | K4: 107068 | L4: 107415 | M4: 107762 | N4: 108110 | O4: 108454 | P4: 108804
A5: 26014 | B5: Cushamen | C5: 28440 | D5: 28582 | E5: 28738 | F5: 28889 | G5: 29031 | H5: 29168 | I5: 29301 | J5: 29428 | K5: 29553 | L5: 29678 | M5: 29802 | N5: 29927 | O5: 30051 | P5: 30176
A6: 26021 | B6: Escalante | C6: 217201 | D6: 217751 | E6: 218354 | F6: 218939 | G6: 219492 | H6: 220024 | I6: 220536 | J6: 221031 | K6: 221517 | L6: 222001 | M6: 222484 | N6: 222968 | O6: 223448 | P6: 223934
A7: 26028 | B7: Florentino Ameghino | C7: 1802 | D7: 1805 | E7: 1808 | F7: 1812 | G7: 1815 | H7: 1818 | I7: 1821 | J7: 1824 | K7: 1827 | L7: 1830 | M7: 1834 | N7: 1837 | O7: 1840 | P7: 1842
A8: 26035 | B8: Futaleufú | C8: 50702 | D8: 50838 | E8: 50985 | F8: 51129 | G8: 51264 | H8: 51394 | I8: 51521 | J8: 51642 | K8: 51761 | L8: 51880 | M8: 51999 | N8: 52117 | O8: 52235 | P8: 52354
A9: 26042 | B9: Gaiman | C9: 12743 | D9: 12771 | E9: 12803 | F9: 12833 | G9: 12862 | H9: 12890 | I9: 12917 | J9: 12943 | K9: 12969 | L9: 12994 | M9: 13019 | N9: 13044 | O9: 13070 | P9: 13094
A10: 26049 | B10: Gastre | C10: 1208 | D10: 1203 | E10: 1198 | F10: 1192 | G10: 1188 | H10: 1182 | I10: 1178 | J10: 1173 | K10: 1169 | L10: 1165 | M10: 1160 | N10: 1155 | O10: 1151 | P10: 1147
A11: 26056 | B11: Languiñeo | C11: 2910 | D11: 2905 | E11: 2901 | F11: 2896 | G11: 2892 | H11: 2888 | I11: 2884 | J11: 2880 | K11: 2876 | L11: 2872 | M11: 2868 | N11: 2865 | O11: 2861 | P11: 2857
A12: 26063 | B12: Mártires | C12: 763 | D12: 763 | E12: 762 | F12: 760 | G12: 760 | H12: 760 | I12: 758 | J12: 758 | K12: 757 | L12: 757 | M12: 757 | N12: 755 | O12: 755 | P12: 754
A13: 26070 | B13: Paso de Indios | C13: 1905 | D13: 1905 | E13: 1905 | F13: 1905 | G13: 1906 | H13: 1906 | I13: 1905 | J13: 1906 | K13: 1906 | L13: 1906 | M13: 1906 | N13: 1907 | O13: 1906 | P13: 1906
A14: 26077 | B14: Rawson | C14: 146903 | D14: 147157 | E14: 147435 | F14: 147704 | G14: 147958 | H14: 148203 | I14: 148438 | J14: 148664 | K14: 148888 | L14: 149110 | M14: 149332 | N14: 149555 | O14: 149774 | P14: 149999
... A18: 26105 | B18: Telsen | C18: 1639 | D18: 1638 | E18: 1637 | F18: 1636 | G18: 1633 | H18: 1632 | I18: 1631 | J18: 1630 | K18: 1629 | L18: 1628 | M18: 1627 | N18: 1626 | O18: 1624 | P18: 1623
A20: Varones
A21: Código | B21: Departamento | C21: 2022 | D21: 2023 | E21: 2024 | F21: 2025 | G21: 2026 | H21: 2027 | I21: 2028 | J21: 2029 | K21: 2030 | L21: 2031 | M21: 2032 | N21: 2033 | O21: 2034 | P21: 2035
A22: 26007 | B22: Biedma | C22: 52290 | D22: 52467 | E22: 52661 | F22: 52835 | G22: 52996 | H22: 53149 | I22: 53298 | J22: 53439 | K22: 53578 | L22: 53719 | M22: 53861 | N22: 54007 | O22: 54149 | P22: 54300
A23: 26014 | B23: Cushamen | C23: 14340 | D23: 14400 | E23: 14466 | F23: 14525 | G23: 14579 | H23: 14631 | I23: 14682 | J23: 14730 | K23: 14777 | L23: 14825 | M23: 14873 | N23: 14922 | O23: 14971 | P23: 15022
A24: 26021 | B24: Escalante | C24: 109000 | D24: 109225 | E24: 109473 | F24: 109695 | G24: 109900 | H24: 110096 | I24: 110285 | J24: 110466 | K24: 110643 | L24: 110823 | M24: 111004 | N24: 111190 | O24: 111372 | P24: 111564
A25: 26028 | B25: Florentino Ameghino | C25: 953 | D25: 953 | E25: 953 | F25: 953 | G25: 953 | H25: 953 | I25: 953 | J25: 953 | K25: 953 | L25: 953 | M25: 954 | N25: 954 | O25: 954 | P25: 954
A26: 26035 | B26: Futaleufú | C26: 24859 | D26: 24915 | E26: 24976 | F26: 25031 | G26: 25082 | H26: 25130 | I26: 25178 | J26: 25222 | K26: 25266 | L26: 25311 | M26: 25356 | N26: 25402 | O26: 25447 | P26: 25494
A27: 26042 | B27: Gaiman | C27: 6445 | D27: 6454 | E27: 6464 | F27: 6473 | G27: 6481 | H27: 6489 | I27: 6496 | J27: 6504 | K27: 6511 | L27: 6518 | M27: 6525 | N27: 6532 | O27: 6540 | P27: 6547
A28: 26049 | B28: Gastre | C28: 694 | D28: 691 | E28: 689 | F28: 686 | G28: 684 | H28: 681 | I28: 679 | J28: 677 | K28: 675 | L28: 673 | M28: 671 | N28: 668 | O28: 666 | P28: 664
A29: 26056 | B29: Languiñeo | C29: 1547 | D29: 1543 | E29: 1540 | F29: 1536 | G29: 1533 | H29: 1530 | I29: 1527 | J29: 1524 | K29: 1521 | L29: 1518 | M29: 1515 | N29: 1512 | O29: 1509 | P29: 1506
A30: 26063 | B30: Mártires | C30: 447 | D30: 447 | E30: 446 | F30: 445 | G30: 445 | H30: 445 | I30: 444 | J30: 444 | K30: 443 | L30: 443 | M30: 443 | N30: 442 | O30: 442 | P30: 441
A31: 26070 | B31: Paso de Indios | C31: 1046 | D31: 1045 | E31: 1044 | F31: 1043 | G31: 1043 | H31: 1042 | I31: 1041 | J31: 1041 | K31: 1040 | L31: 1039 | M31: 1038 | N31: 1038 | O31: 1037 | P31: 1036
A32: 26077 | B32: Rawson | C32: 72632 | D32: 72743 | E32: 72866 | F32: 72976 | G32: 73077 | H32: 73174 | I32: 73268 | J32: 73357 | K32: 73445 | L32: 73534 | M32: 73624 | N32: 73716 | O32: 73805 | P32: 73901
... A36: 26105 | B36: Telsen | C36: 899 | D36: 899 | E36: 899 | F36: 899 | G36: 898 | H36: 898 | I36: 898 | J36: 898 | K36: 898 | L36: 898 | M36: 898 | N36: 898 | O36: 897 | P36: 897
A38: Mujeres
A39: Código | B39: Departamento | C39: 2022 | D39: 2023 | E39: 2024 | F39: 2025 | G39: 2026 | H39: 2027 | I39: 2028 | J39: 2029 | K39: 2030 | L39: 2031 | M39: 2032 | N39: 2033 | O39: 2034 | P39: 2035
A40: 26007 | B40: Biedma | C40: 51680 | D40: 51901 | E40: 52141 | F40: 52387 | G40: 52622 | H40: 52851 | I40: 53069 | J40: 53282 | K40: 53490 | L40: 53696 | M40: 53901 | N40: 54103 | O40: 54305 | P40: 54504
A41: 26014 | B41: Cushamen | C41: 14100 | D41: 14182 | E41: 14272 | F41: 14364 | G41: 14452 | H41: 14537 | I41: 14619 | J41: 14698 | K41: 14776 | L41: 14853 | M41: 14929 | N41: 15005 | O41: 15080 | P41: 15154
A42: 26021 | B42: Escalante | C42: 108201 | D42: 108526 | E42: 108881 | F42: 109244 | G42: 109592 | H42: 109928 | I42: 110251 | J42: 110565 | K42: 110874 | L42: 111178 | M42: 111480 | N42: 111778 | O42: 112076 | P42: 112370
A43: 26028 | B43: Florentino Ameghino | C43: 849 | D43: 852 | E43: 855 | F43: 859 | G43: 862 | H43: 865 | I43: 868 | J43: 871 | K43: 874 | L43: 877 | M43: 880 | N43: 883 | O43: 886 | P43: 888
A44: 26035 | B44: Futaleufú | C44: 25843 | D44: 25923 | E44: 26009 | F44: 26098 | G44: 26182 | H44: 26264 | I44: 26343 | J44: 26420 | K44: 26495 | L44: 26569 | M44: 26643 | N44: 26715 | O44: 26788 | P44: 26860
A45: 26042 | B45: Gaiman | C45: 6298 | D45: 6317 | E45: 6339 | F45: 6360 | G45: 6381 | H45: 6401 | I45: 6421 | J45: 6439 | K45: 6458 | L45: 6476 | M45: 6494 | N45: 6512 | O45: 6530 | P45: 6547
A46: 26049 | B46: Gastre | C46: 514 | D46: 512 | E46: 509 | F46: 506 | G46: 504 | H46: 501 | I46: 499 | J46: 496 | K46: 494 | L46: 492 | M46: 489 | N46: 487 | O46: 485 | P46: 483
A47: 26056 | B47: Languiñeo | C47: 1363 | D47: 1362 | E47: 1361 | F47: 1360 | G47: 1359 | H47: 1358 | I47: 1357 | J47: 1356 | K47: 1355 | L47: 1354 | M47: 1353 | N47: 1353 | O47: 1352 | P47: 1351
A48: 26063 | B48: Mártires | C48: 316 | D48: 316 | E48: 316 | F48: 315 | G48: 315 | H48: 315 | I48: 314 | J48: 314 | K48: 314 | L48: 314 | M48: 314 | N48: 313 | O48: 313 | P48: 313
...

Sheet 30-ENTRE RÍOS
A1: Cuadro 8. Provincia de Entre Ríos. Población estimada al 1.° de julio de cada año calendario, por sexo, según departamento. Años 2022-2035
A2: Ambos sexos
A3: Código | B3: Departamento | C3: 2022 | D3: 2023 | E3: 2024 | F3: 2025 | G3: 2026 | H3: 2027 | I3: 2028 | J3: 2029 | K3: 2030 | L3: 2031 | M3: 2032 | N3: 2033 | O3: 2034 | P3: 2035
A4: 30008 | B4: Colón | C4: 76600 | D4: 76833 | E4: 77095 | F4: 77348 | G4: 77583 | H4: 77802 | I4: 78008 | J4: 78204 | K4: 78395 | L4: 78590 | M4: 78784 | N4: 78982 | O4: 79179 | P4: 79376
A5: 30015 | B5: Concordia | C5: 202203 | D5: 202668 | E5: 203191 | F5: 203694 | G5: 204165 | H5: 204601 | I5: 205012 | J5: 205402 | K5: 205782 | L5: 206171 | M5: 206560 | N5: 206953 | O5: 207344 | P5: 207739
A6: 30021 | B6: Diamante | C6: 54511 | D6: 54623 | E6: 54750 | F6: 54871 | G6: 54986 | H6: 55091 | I6: 55191 | J6: 55285 | K6: 55378 | L6: 55473 | M6: 55568 | N6: 55663 | O6: 55759 | P6: 55855
A7: 30028 | B7: Federación | C7: 79978 | D7: 80131 | E7: 80303 | F7: 80468 | G7: 80623 | H7: 80766 | I7: 80901 | J7: 81030 | K7: 81156 | L7: 81284 | M7: 81412 | N7: 81543 | O7: 81672 | P7: 81802
A8: 30035 | B8: Federal | C8: 30181 | D8: 30239 | E8: 30303 | F8: 30364 | G8: 30423 | H8: 30476 | I8: 30527 | J8: 30575 | K8: 30622 | L8: 30670 | M8: 30719 | N8: 30767 | O8: 30816 | P8: 30865
A9: 30042 | B9: Feliciano | C9: 17091 | D9: 17114 | E9: 17138 | F9: 17162 | G9: 17185 | H9: 17206 | I9: 17226 | J9: 17245 | K9: 17262 | L9: 17281 | M9: 17299 | N9: 17318 | O9: 17337 | P9: 17356
A10: 30049 | B10: Gualeguay | C10: 58284 | D10: 58351 | E10: 58426 | F10: 58499 | G10: 58566 | H10: 58629 | I10: 58688 | J10: 58745 | K10: 58800 | L10: 58857 | M10: 58913 | N10: 58970 | O10: 59028 | P10: 59084
A11: 30056 | B11: Gualeguaychú | C11: 128304 | D11: 128563 | E11: 128854 | F11: 129133 | G11: 129396 | H11: 129639 | I11: 129867 | J11: 130085 | K11: 130296 | L11: 130514 | M11: 130731 | N11: 130951 | O11: 131171 | P11: 131390
A12: 30063 | B12: Islas del Ibicuy | C12: 14246 | D12: 14277 | E12: 14310 | F12: 14342 | G12: 14373 | H12: 14401 | I12: 14428 | J12: 14454 | K12: 14478 | L12: 14503 | M12: 14528 | N12: 14554 | O12: 14579 | P12: 14605
A13: 30070 | B13: La Paz | C13: 76701 | D13: 76818 | E13: 76950 | F13: 77076 | G13: 77194 | H13: 77305 | I13: 77408 | J13: 77507 | K13: 77603 | L13: 77701 | M13: 77799 | N13: 77899 | O13: 77999 | P13: 78098
